Workbook

Sheet Guide
A1: ADN Tap-to-Earn Progression Model
A3: Section | B3: Description
A4: What this file is | B4: Original, genre-inspired balancing workbook for an ADN-themed tap-to-earn mining app. It is not a direct clone of any existing game.
A5: Core loop | B5: Tap for active earnings, buy upgrades for hourly ADN production, progress through player levels, unlock systems, and push toward airdrop-weight milestones.
A6: How to use | B6: 1) Edit only blue cells on Controls or Upgrade_Params. 2) Review level pacing on Player_Levels. 3) Review card pricing and hourly gain on Upgrade_Tiers. 4) Use Dashboard for KPI sense-checks.
A7: Design goals | B7: Fast early progression, meaningful midgame choice, slower but still rewarding late-game compounding, and anti-farm referral progression.
A8: Economy note | B8: ADN in this workbook is treated as an in-game earn/spend unit. Real token, cash-out, or airdrop conversion should be gated behind compliance, fraud review, and snapshot logic.
A10: Recommended Game Feel by Phase
A11: Phase | B11: Player Levels | C11: Session Feel | D11: Main Unlock Focus | E11: Target Hourly ADN | F11: Primary Sink | G11: Primary Reward
A12: Starter | B12: 1-6 | C12: Very fast taps, instant upgrades | D12: Core cards, daily bonus, streaks | E12: 50-600 | F12: Starter cards | G12: Hook + competence
A13: Early Midgame | B13: 7-15 | C13: First real choices appear | D13: Referral chain, idle play, creator cards | E13: 600-6,000 | F13: Efficiency upgrades | G13: Agency + discovery
A14: Midgame | B14: 16-28 | C14: Build identity around category bets | D14: Guilds, premium market, auto-tap | E14: 6,000-65,000 | F14: Compounding cards | G14: Strategic optimization
A15: Late Midgame | B15: 29-40 | C15: Progress slower but meaningful | D15: Whale analytics, elite missions | E15: 65,000-550,000 | F15: High-tier finance/research | G15: Status + rarity
A16: Endgame | B16: 41-50 | C16: Prestige and airdrop prep | D16: Claim readiness, long offline cap | E16: 550,000-3,000,000 | F16: Tier 12-15 cards | G16: Retention + collection

Sheet Controls
A1: Balance Controls
A3: Control | B3: Value | C3: Notes
A4: Base XP to next level | B4: 120 | C4: Used in XP curve. | E4: Quick KPI Readout
A5: XP exponent | B5: 1.43 | C5: Higher = steeper level curve. | E5: Level 10 XP to next | F5: =ROUND($B$4*(10^$B$5),0)
A6: Base tap reward | B6: 1 | C6: Starter active reward per tap. | E6: Level 25 tap reward | F6: =ROUND($B$6*(1+$B$7)^(25-1),2)
A7: Tap reward growth / level | B7: 0.04 | C7: 4% per player level. | E7: Level 35 offline cap | F7: =MIN($B$15,$B$13+(35-1)*$B$14)
A8: Base max energy | B8: 500 | C8: Starter energy pool. | E8: Level 50 passive cap / hr | F8: =ROUND($B$16*(1+$B$17)^(50-1),0)
A9: Energy per player level | B9: 30 | C9: Flat increase each level.
A10: Base energy regen / min | B10: 8 | C10: Starter refill rate.
A11: Regen step levels | B11: 5 | C11: Increase regen every N levels.
A12: Regen increase / step | B12: 1 | C12: Flat regen increase.
A13: Base offline cap hours | B13: 3 | C13: Starter idle earning cap.
A14: Offline cap hours / level | B14: 0.25 | C14: Growth per level.
A15: Offline cap max hours | B15: 12 | C15: Hard cap to control inflation.
A16: Base passive cap / hour | B16: 250 | C16: Soft target for early passive economy.
A17: Passive cap growth / level | B17: 0.18 | C17: Compounded cap growth.
A18: Base airdrop weight / 1k earned | B18: 2 | C18: Optional snapshot weight proxy.
A19: Airdrop weight growth / level | B19: 0.015 | C19: Scales long-term grinders.

Sheet Feature_Unlocks
A1: Feature Unlock Roadmap
A3: Player Level | B3: Feature / System | C3: Purpose | D3: Why It Unlocks Here | E3: Reward Direction | F3: Abuse / Risk Notes | G3: Ops Notes
A4: 1 | B4: Starter Tap + 4 starter cards | C4: Creates instant loop | D4: Immediate engagement | E4: Fast ADN flow | F4: No referral rewards yet | G4: Tutorial only
A5: 2 | B5: Daily bonus | C5: First retention hook | D5: After first session understanding | E5: Flat daily ADN | F5: 1 claim / 20h | G5: Reset at UTC or local midnight
A6: 3 | B6: Referral Hub | C6: Introduce social growth | D6: User understands basic spend loop | E6: Invite bonus + ADN | F6: No self-referral | G6: Track device/IP
A7: 5 | B7: Streak multiplier | C7: Second retention layer | D7: Daily habit now matters | E7: +% daily reward | F7: Break protection limited | G7: Offer one rescue / week
A8: 6 | B8: GPU / ASIC cards | C8: Passive compounding begins | D8: Enough ADN to branch choices | E8: Higher hourly ADN | F8: Cap idle claim | G8: Shift to passive build
A9: 8 | B9: Referral Quest Chain | C9: Quality referrals over raw invites | D9: User ready for objective-based social | E9: ADN + airdrop weight | F9: Only active referrals count | G9: Quest engine online
A10: 10 | B10: Creator Bounties | C10: UGC-style growth | D10: Players seek faster progression | E10: ADN + badge | F10: Manual moderation if needed | G10: Promo hooks
A11: 12 | B11: Quantum Cooling / longer idle | C11: Idle comfort upgrade | D11: Midgame pacing needs breathing room | E11: More offline hours | F11: Keep max cap in place | G11: Good reactivation trigger
A12: 15 | B12: Premium Market | C12: Higher-value spend sink | D12: Monetization gate after habit formed | E12: Access to advanced cards | F12: Offer responsibly | G12: Stars / premium hooks
A13: 18 | B13: Guild Program | C13: Social retention | D13: Enough economy depth for co-op | E13: Guild quests | F13: Limit alt-account farming | G13: Seasonal races
A14: 22 | B14: Auto-Tap Drones | C14: Convenience power spike | D14: Midgame friction starts rising | E14: More idle efficiency | F14: Rate limit outputs | G14: Server-side anti-cheat
A15: 25 | B15: Seasonal Leaderboards | C15: Status loop | D15: Core audience now invested | E15: Cosmetic + weight rewards | F15: Fraud filters mandatory | G15: Manual fraud review
... A21: 50 | B21: Legend Tier + Prestige badge | C21: Long horizon target | D21: Retains top 1-5% grinders | E21: Cosmetic + weight bonus | F21: No infinite loop reset by default | G21: Season pass or prestige later

Sheet Player_Levels
A1: Player Level Curve
A3: Level | B3: XP to Next | C3: Cumulative XP | D3: Tap Reward | E3: Max Energy | F3: Regen / Min | G3: Offline Cap Hrs | H3: Passive Cap / Hr | I3: Airdrop Weight / 1k | J3: Milestone Unlock | K3: Retention Intent
A4: 1 | B4: =ROUND(Controls!$B$4*(A4^Controls!$B$5),0) | C4: =SUM($B$4:B4) | D4: =ROUND(Controls!$B$6*(1+Controls!$B$7)^(A4-1),2) | E4: =Controls!$B$8+Controls!$B$9*(A4-1) | F4: =Controls!$B$10+INT((A4-1)/Controls!$B$11)*Controls!$B$12 | G4: =MIN(Controls!$B$15,Controls!$B$13+(A4-1)*Controls!$B$14) | H4: =ROUND(Controls!$B$16*(1+Controls!$B$17)^(A4-1),0) | I4: =ROUND(Controls!$B$18*(1+Controls!$B$19)^(A4-1),2) | J4: Starter Tap + 4 starter cards | K4: Hook
A5: 2 | B5: =ROUND(Controls!$B$4*(A5^Controls!$B$5),0) | C5: =SUM($B$4:B5) | D5: =ROUND(Controls!$B$6*(1+Controls!$B$7)^(A5-1),2) | E5: =Controls!$B$8+Controls!$B$9*(A5-1) | F5: =Controls!$B$10+INT((A5-1)/Controls!$B$11)*Controls!$B$12 | G5: =MIN(Controls!$B$15,Controls!$B$13+(A5-1)*Controls!$B$14) | H5: =ROUND(Controls!$B$16*(1+Controls!$B$17)^(A5-1),0) | I5: =ROUND(Controls!$B$18*(1+Controls!$B$19)^(A5-1),2) | J5: Daily bonus | K5: Retention seed
A6: 3 | B6: =ROUND(Controls!$B$4*(A6^Controls!$B$5),0) | C6: =SUM($B$4:B6) | D6: =ROUND(Controls!$B$6*(1+Controls!$B$7)^(A6-1),2) | E6: =Controls!$B$8+Controls!$B$9*(A6-1) | F6: =Controls!$B$10+INT((A6-1)/Controls!$B$11)*Controls!$B$12 | G6: =MIN(Controls!$B$15,Controls!$B$13+(A6-1)*Controls!$B$14) | H6: =ROUND(Controls!$B$16*(1+Controls!$B$17)^(A6-1),0) | I6: =ROUND(Controls!$B$18*(1+Controls!$B$19)^(A6-1),2) | J6: Referral Hub | K6: Social intro
A7: 4 | B7: =ROUND(Controls!$B$4*(A7^Controls!$B$5),0) | C7: =SUM($B$4:B7) | D7: =ROUND(Controls!$B$6*(1+Controls!$B$7)^(A7-1),2) | E7: =Controls!$B$8+Controls!$B$9*(A7-1) | F7: =Controls!$B$10+INT((A7-1)/Controls!$B$11)*Controls!$B$12 | G7: =MIN(Controls!$B$15,Controls!$B$13+(A7-1)*Controls!$B$14) | H7: =ROUND(Controls!$B$16*(1+Controls!$B$17)^(A7-1),0) | I7: =ROUND(Controls!$B$18*(1+Controls!$B$19)^(A7-1),2)
A8: 5 | B8: =ROUND(Controls!$B$4*(A8^Controls!$B$5),0) | C8: =SUM($B$4:B8) | D8: =ROUND(Controls!$B$6*(1+Controls!$B$7)^(A8-1),2) | E8: =Controls!$B$8+Controls!$B$9*(A8-1) | F8: =Controls!$B$10+INT((A8-1)/Controls!$B$11)*Controls!$B$12 | G8: =MIN(Controls!$B$15,Controls!$B$13+(A8-1)*Controls!$B$14) | H8: =ROUND(Controls!$B$16*(1+Controls!$B$17)^(A8-1),0) | I8: =ROUND(Controls!$B$18*(1+Controls!$B$19)^(A8-1),2) | J8: Streak multiplier | K8: Habit loop
A9: 6 | B9: =ROUND(Controls!$B$4*(A9^Controls!$B$5),0) | C9: =SUM($B$4:B9) | D9: =ROUND(Controls!$B$6*(1+Controls!$B$7)^(A9-1),2) | E9: =Controls!$B$8+Controls!$B$9*(A9-1) | F9: =Controls!$B$10+INT((A9-1)/Controls!$B$11)*Controls!$B$12 | G9: =MIN(Controls!$B$15,Controls!$B$13+(A9-1)*Controls!$B$14) | H9: =ROUND(Controls!$B$16*(1+Controls!$B$17)^(A9-1),0) | I9: =ROUND(Controls!$B$18*(1+Controls!$B$19)^(A9-1),2) | J9: GPU / ASIC cards
A10: 7 | B10: =ROUND(Controls!$B$4*(A10^Controls!$B$5),0) | C10: =SUM($B$4:B10) | D10: =ROUND(Controls!$B$6*(1+Controls!$B$7)^(A10-1),2) | E10: =Controls!$B$8+Controls!$B$9*(A10-1) | F10: =Controls!$B$10+INT((A10-1)/Controls!$B$11)*Controls!$B$12 | G10: =MIN(Controls!$B$15,Controls!$B$13+(A10-1)*Controls!$B$14) | H10: =ROUND(Controls!$B$16*(1+Controls!$B$17)^(A10-1),0) | I10: =ROUND(Controls!$B$18*(1+Controls!$B$19)^(A10-1),2)
A11: 8 | B11: =ROUND(Controls!$B$4*(A11^Controls!$B$5),0) | C11: =SUM($B$4:B11) | D11: =ROUND(Controls!$B$6*(1+Controls!$B$7)^(A11-1),2) | E11: =Controls!$B$8+Controls!$B$9*(A11-1) | F11: =Controls!$B$10+INT((A11-1)/Controls!$B$11)*Controls!$B$12 | G11: =MIN(Controls!$B$15,Controls!$B$13+(A11-1)*Controls!$B$14) | H11: =ROUND(Controls!$B$16*(1+Controls!$B$17)^(A11-1),0) | I11: =ROUND(Controls!$B$18*(1+Controls!$B$19)^(A11-1),2) | J11: Referral Quest Chain | K11: Quality referrals
A12: 9 | B12: =ROUND(Controls!$B$4*(A12^Controls!$B$5),0) | C12: =SUM($B$4:B12) | D12: =ROUND(Controls!$B$6*(1+Controls!$B$7)^(A12-1),2) | E12: =Controls!$B$8+Controls!$B$9*(A12-1) | F12: =Controls!$B$10+INT((A12-1)/Controls!$B$11)*Controls!$B$12 | G12: =MIN(Controls!$B$15,Controls!$B$13+(A12-1)*Controls!$B$14) | H12: =ROUND(Controls!$B$16*(1+Controls!$B$17)^(A12-1),0) | I12: =ROUND(Controls!$B$18*(1+Controls!$B$19)^(A12-1),2)
A13: 10 | B13: =ROUND(Controls!$B$4*(A13^Controls!$B$5),0) | C13: =SUM($B$4:B13) | D13: =ROUND(Controls!$B$6*(1+Controls!$B$7)^(A13-1),2) | E13: =Controls!$B$8+Controls!$B$9*(A13-1) | F13: =Controls!$B$10+INT((A13-1)/Controls!$B$11)*Controls!$B$12 | G13: =MIN(Controls!$B$15,Controls!$B$13+(A13-1)*Controls!$B$14) | H13: =ROUND(Controls!$B$16*(1+Controls!$B$17)^(A13-1),0) | I13: =ROUND(Controls!$B$18*(1+Controls!$B$19)^(A13-1),2) | J13: Creator Bounties
A14: 11 | B14: =ROUND(Controls!$B$4*(A14^Controls!$B$5),0) | C14: =SUM($B$4:B14) | D14: =ROUND(Controls!$B$6*(1+Controls!$B$7)^(A14-1),2) | E14: =Controls!$B$8+Controls!$B$9*(A14-1) | F14: =Controls!$B$10+INT((A14-1)/Controls!$B$11)*Controls!$B$12 | G14: =MIN(Controls!$B$15,Controls!$B$13+(A14-1)*Controls!$B$14) | H14: =ROUND(Controls!$B$16*(1+Controls!$B$17)^(A14-1),0) | I14: =ROUND(Controls!$B$18*(1+Controls!$B$19)^(A14-1),2)
A15: 12 | B15: =ROUND(Controls!$B$4*(A15^Controls!$B$5),0) | C15: =SUM($B$4:B15) | D15: =ROUND(Controls!$B$6*(1+Controls!$B$7)^(A15-1),2) | E15: =Controls!$B$8+Controls!$B$9*(A15-1) | F15: =Controls!$B$10+INT((A15-1)/Controls!$B$11)*Controls!$B$12 | G15: =MIN(Controls!$B$15,Controls!$B$13+(A15-1)*Controls!$B$14) | H15: =ROUND(Controls!$B$16*(1+Controls!$B$17)^(A15-1),0) | I15: =ROUND(Controls!$B$18*(1+Controls!$B$19)^(A15-1),2) | J15: Quantum Cooling / longer idle | K15: Comfort
A16: 13 | B16: =ROUND(Controls!$B$4*(A16^Controls!$B$5),0) | C16: =SUM($B$4:B16) | D16: =ROUND(Controls!$B$6*(1+Controls!$B$7)^(A16-1),2) | E16: =Controls!$B$8+Controls!$B$9*(A16-1) | F16: =Controls!$B$10+INT((A16-1)/Controls!$B$11)*Controls!$B$12 | G16: =MIN(Controls!$B$15,Controls!$B$13+(A16-1)*Controls!$B$14) | H16: =ROUND(Controls!$B$16*(1+Controls!$B$17)^(A16-1),0) | I16: =ROUND(Controls!$B$18*(1+Controls!$B$19)^(A16-1),2)
A17: 14 | B17: =ROUND(Controls!$B$4*(A17^Controls!$B$5),0) | C17: =SUM($B$4:B17) | D17: =ROUND(Controls!$B$6*(1+Controls!$B$7)^(A17-1),2) | E17: =Controls!$B$8+Controls!$B$9*(A17-1) | F17: =Controls!$B$10+INT((A17-1)/Controls!$B$11)*Controls!$B$12 | G17: =MIN(Controls!$B$15,Controls!$B$13+(A17-1)*Controls!$B$14) | H17: =ROUND(Controls!$B$16*(1+Controls!$B$17)^(A17-1),0) | I17: =ROUND(Controls!$B$18*(1+Controls!$B$19)^(A17-1),2)
A18: 15 | B18: =ROUND(Controls!$B$4*(A18^Controls!$B$5),0) | C18: =SUM($B$4:B18) | D18: =ROUND(Controls!$B$6*(1+Controls!$B$7)^(A18-1),2) | E18: =Controls!$B$8+Controls!$B$9*(A18-1) | F18: =Controls!$B$10+INT((A18-1)/Controls!$B$11)*Controls!$B$12 | G18: =MIN(Controls!$B$15,Controls!$B$13+(A18-1)*Controls!$B$14) | H18: =ROUND(Controls!$B$16*(1+Controls!$B$17)^(A18-1),0) | I18: =ROUND(Controls!$B$18*(1+Controls!$B$19)^(A18-1),2) | J18: Premium Market | K18: Monetization optional
A19: 16 | B19: =ROUND(Controls!$B$4*(A19^Controls!$B$5),0) | C19: =SUM($B$4:B19) | D19: =ROUND(Controls!$B$6*(1+Controls!$B$7)^(A19-1),2) | E19: =Controls!$B$8+Controls!$B$9*(A19-1) | F19: =Controls!$B$10+INT((A19-1)/Controls!$B$11)*Controls!$B$12 | G19: =MIN(Controls!$B$15,Controls!$B$13+(A19-1)*Controls!$B$14) | H19: =ROUND(Controls!$B$16*(1+Controls!$B$17)^(A19-1),0) | I19: =ROUND(Controls!$B$18*(1+Controls!$B$19)^(A19-1),2)
A20: 17 | B20: =ROUND(Controls!$B$4*(A20^Controls!$B$5),0) | C20: =SUM($B$4:B20) | D20: =ROUND(Controls!$B$6*(1+Controls!$B$7)^(A20-1),2) | E20: =Controls!$B$8+Controls!$B$9*(A20-1) | F20: =Controls!$B$10+INT((A20-1)/Controls!$B$11)*Controls!$B$12 | G20: =MIN(Controls!$B$15,Controls!$B$13+(A20-1)*Controls!$B$14) | H20: =ROUND(Controls!$B$16*(1+Controls!$B$17)^(A20-1),0) | I20: =ROUND(Controls!$B$18*(1+Controls!$B$19)^(A20-1),2)
A21: 18 | B21: =ROUND(Controls!$B$4*(A21^Controls!$B$5),0) | C21: =SUM($B$4:B21) | D21: =ROUND(Controls!$B$6*(1+Controls!$B$7)^(A21-1),2) | E21: =Controls!$B$8+Controls!$B$9*(A21-1) | F21: =Controls!$B$10+INT((A21-1)/Controls!$B$11)*Controls!$B$12 | G21: =MIN(Controls!$B$15,Controls!$B$13+(A21-1)*Controls!$B$14) | H21: =ROUND(Controls!$B$16*(1+Controls!$B$17)^(A21-1),0) | I21: =ROUND(Controls!$B$18*(1+Controls!$B$19)^(A21-1),2) | J21: Guild Program | K21: Social depth
A22: 19 | B22: =ROUND(Controls!$B$4*(A22^Controls!$B$5),0) | C22: =SUM($B$4:B22) | D22: =ROUND(Controls!$B$6*(1+Controls!$B$7)^(A22-1),2) | E22: =Controls!$B$8+Controls!$B$9*(A22-1) | F22: =Controls!$B$10+INT((A22-1)/Controls!$B$11)*Controls!$B$12 | G22: =MIN(Controls!$B$15,Controls!$B$13+(A22-1)*Controls!$B$14) | H22: =ROUND(Controls!$B$16*(1+Controls!$B$17)^(A22-1),0) | I22: =ROUND(Controls!$B$18*(1+Controls!$B$19)^(A22-1),2)
A23: 20 | B23: =ROUND(Controls!$B$4*(A23^Controls!$B$5),0) | C23: =SUM($B$4:B23) | D23: =ROUND(Controls!$B$6*(1+Controls!$B$7)^(A23-1),2) | E23: =Controls!$B$8+Controls!$B$9*(A23-1) | F23: =Controls!$B$10+INT((A23-1)/Controls!$B$11)*Controls!$B$12 | G23: =MIN(Controls!$B$15,Controls!$B$13+(A23-1)*Controls!$B$14) | H23: =ROUND(Controls!$B$16*(1+Controls!$B$17)^(A23-1),0) | I23: =ROUND(Controls!$B$18*(1+Controls!$B$19)^(A23-1),2)
A24: 21 | B24: =ROUND(Controls!$B$4*(A24^Controls!$B$5),0) | C24: =SUM($B$4:B24) | D24: =ROUND(Controls!$B$6*(1+Controls!$B$7)^(A24-1),2) | E24: =Controls!$B$8+Controls!$B$9*(A24-1) | F24: =Controls!$B$10+INT((A24-1)/Controls!$B$11)*Controls!$B$12 | G24: =MIN(Controls!$B$15,Controls!$B$13+(A24-1)*Controls!$B$14) | H24: =ROUND(Controls!$B$16*(1+Controls!$B$17)^(A24-1),0) | I24: =ROUND(Controls!$B$18*(1+Controls!$B$19)^(A24-1),2)
A25: 22 | B25: =ROUND(Controls!$B$4*(A25^Controls!$B$5),0) | C25: =SUM($B$4:B25) | D25: =ROUND(Controls!$B$6*(1+Controls!$B$7)^(A25-1),2) | E25: =Controls!$B$8+Controls!$B$9*(A25-1) | F25: =Controls!$B$10+INT((A25-1)/Controls!$B$11)*Controls!$B$12 | G25: =MIN(Controls!$B$15,Controls!$B$13+(A25-1)*Controls!$B$14) | H25: =ROUND(Controls!$B$16*(1+Controls!$B$17)^(A25-1),0) | I25: =ROUND(Controls!$B$18*(1+Controls!$B$19)^(A25-1),2) | J25: Auto-Tap Drones | K25: Convenience
A26: 23 | B26: =ROUND(Controls!$B$4*(A26^Controls!$B$5),0) | C26: =SUM($B$4:B26) | D26: =ROUND(Controls!$B$6*(1+Controls!$B$7)^(A26-1),2) | E26: =Controls!$B$8+Controls!$B$9*(A26-1) | F26: =Controls!$B$10+INT((A26-1)/Controls!$B$11)*Controls!$B$12 | G26: =MIN(Controls!$B$15,Controls!$B$13+(A26-1)*Controls!$B$14) | H26: =ROUND(Controls!$B$16*(1+Controls!$B$17)^(A26-1),0) | I26: =ROUND(Controls!$B$18*(1+Controls!$B$19)^(A26-1),2)
A27: 24 | B27: =ROUND(Controls!$B$4*(A27^Controls!$B$5),0) | C27: =SUM($B$4:B27) | D27: =ROUND(Controls!$B$6*(1+Controls!$B$7)^(A27-1),2) | E27: =Controls!$B$8+Controls!$B$9*(A27-1) | F27: =Controls!$B$10+INT((A27-1)/Controls!$B$11)*Controls!$B$12 | G27: =MIN(Controls!$B$15,Controls!$B$13+(A27-1)*Controls!$B$14) | H27: =ROUND(Controls!$B$16*(1+Controls!$B$17)^(A27-1),0) | I27: =ROUND(Controls!$B$18*(1+Controls!$B$19)^(A27-1),2)
A28: 25 | B28: =ROUND(Controls!$B$4*(A28^Controls!$B$5),0) | C28: =SUM($B$4:B28) | D28: =ROUND(Controls!$B$6*(1+Controls!$B$7)^(A28-1),2) | E28: =Controls!$B$8+Controls!$B$9*(A28-1) | F28: =Controls!$B$10+INT((A28-1)/Controls!$B$11)*Controls!$B$12 | G28: =MIN(Controls!$B$15,Controls!$B$13+(A28-1)*Controls!$B$14) | H28: =ROUND(Controls!$B$16*(1+Controls!$B$17)^(A28-1),0) | I28: =ROUND(Controls!$B$18*(1+Controls!$B$19)^(A28-1),2) | J28: Seasonal Leaderboards | K28: Status
A29: 26 | B29: =ROUND(Controls!$B$4*(A29^Controls!$B$5),0) | C29: =SUM($B$4:B29) | D29: =ROUND(Controls!$B$6*(1+Controls!$B$7)^(A29-1),2) | E29: =Controls!$B$8+Controls!$B$9*(A29-1) | F29: =Controls!$B$10+INT((A29-1)/Controls!$B$11)*Controls!$B$12 | G29: =MIN(Controls!$B$15,Controls!$B$13+(A29-1)*Controls!$B$14) | H29: =ROUND(Controls!$B$16*(1+Controls!$B$17)^(A29-1),0) | I29: =ROUND(Controls!$B$18*(1+Controls!$B$19)^(A29-1),2)
A30: 27 | B30: =ROUND(Controls!$B$4*(A30^Controls!$B$5),0) | C30: =SUM($B$4:B30) | D30: =ROUND(Controls!$B$6*(1+Controls!$B$7)^(A30-1),2) | E30: =Controls!$B$8+Controls!$B$9*(A30-1) | F30: =Controls!$B$10+INT((A30-1)/Controls!$B$11)*Controls!$B$12 | G30: =MIN(Controls!$B$15,Controls!$B$13+(A30-1)*Controls!$B$14) | H30: =ROUND(Controls!$B$16*(1+Controls!$B$17)^(A30-1),0) | I30: =ROUND(Controls!$B$18*(1+Controls!$B$19)^(A30-1),2)
A31: 28 | B31: =ROUND(Controls!$B$4*(A31^Controls!$B$5),0) | C31: =SUM($B$4:B31) | D31: =ROUND(Controls!$B$6*(1+Controls!$B$7)^(A31-1),2) | E31: =Controls!$B$8+Controls!$B$9*(A31-1) | F31: =Controls!$B$10+INT((A31-1)/Controls!$B$11)*Controls!$B$12 | G31: =MIN(Controls!$B$15,Controls!$B$13+(A31-1)*Controls!$B$14) | H31: =ROUND(Controls!$B$16*(1+Controls!$B$17)^(A31-1),0) | I31: =ROUND(Controls!$B$18*(1+Controls!$B$19)^(A31-1),2) | J31: Smart Missions | K31: Personalization
A32: 29 | B32: =ROUND(Controls!$B$4*(A32^Controls!$B$5),0) | C32: =SUM($B$4:B32) | D32: =ROUND(Controls!$B$6*(1+Controls!$B$7)^(A32-1),2) | E32: =Controls!$B$8+Controls!$B$9*(A32-1) | F32: =Controls!$B$10+INT((A32-1)/Controls!$B$11)*Controls!$B$12 | G32: =MIN(Controls!$B$15,Controls!$B$13+(A32-1)*Controls!$B$14) | H32: =ROUND(Controls!$B$16*(1+Controls!$B$17)^(A32-1),0) | I32: =ROUND(Controls!$B$18*(1+Controls!$B$19)^(A32-1),2)
A33: 30 | B33: =ROUND(Controls!$B$4*(A33^Controls!$B$5),0) | C33: =SUM($B$4:B33) | D33: =ROUND(Controls!$B$6*(1+Controls!$B$7)^(A33-1),2) | E33: =Controls!$B$8+Controls!$B$9*(A33-1) | F33: =Controls!$B$10+INT((A33-1)/Controls!$B$11)*Controls!$B$12 | G33: =MIN(Controls!$B$15,Controls!$B$13+(A33-1)*Controls!$B$14) | H33: =ROUND(Controls!$B$16*(1+Controls!$B$17)^(A33-1),0) | I33: =ROUND(Controls!$B$18*(1+Controls!$B$19)^(A33-1),2) | J33: Whale Analytics | K33: Advanced spender
A34: 31 | B34: =ROUND(Controls!$B$4*(A34^Controls!$B$5),0) | C34: =SUM($B$4:B34) | D34: =ROUND(Controls!$B$6*(1+Controls!$B$7)^(A34-1),2) | E34: =Controls!$B$8+Controls!$B$9*(A34-1) | F34: =Controls!$B$10+INT((A34-1)/Controls!$B$11)*Controls!$B$12 | G34: =MIN(Controls!$B$15,Controls!$B$13+(A34-1)*Controls!$B$14) | H34: =ROUND(Controls!$B$16*(1+Controls!$B$17)^(A34-1),0) | I34: =ROUND(Controls!$B$18*(1+Controls!$B$19)^(A34-1),2)
A35: 32 | B35: =ROUND(Controls!$B$4*(A35^Controls!$B$5),0) | C35: =SUM($B$4:B35) | D35: =ROUND(Controls!$B$6*(1+Controls!$B$7)^(A35-1),2) | E35: =Controls!$B$8+Controls!$B$9*(A35-1) | F35: =Controls!$B$10+INT((A35-1)/Controls!$B$11)*Controls!$B$12 | G35: =MIN(Controls!$B$15,Controls!$B$13+(A35-1)*Controls!$B$14) | H35: =ROUND(Controls!$B$16*(1+Controls!$B$17)^(A35-1),0) | I35: =ROUND(Controls!$B$18*(1+Controls!$B$19)^(A35-1),2)
A36: 33 | B36: =ROUND(Controls!$B$4*(A36^Controls!$B$5),0) | C36: =SUM($B$4:B36) | D36: =ROUND(Controls!$B$6*(1+Controls!$B$7)^(A36-1),2) | E36: =Controls!$B$8+Controls!$B$9*(A36-1) | F36: =Controls!$B$10+INT((A36-1)/Controls!$B$11)*Controls!$B$12 | G36: =MIN(Controls!$B$15,Controls!$B$13+(A36-1)*Controls!$B$14) | H36: =ROUND(Controls!$B$16*(1+Controls!$B$17)^(A36-1),0) | I36: =ROUND(Controls!$B$18*(1+Controls!$B$19)^(A36-1),2)
A37: 34 | B37: =ROUND(Controls!$B$4*(A37^Controls!$B$5),0) | C37: =SUM($B$4:B37) | D37: =ROUND(Controls!$B$6*(1+Controls!$B$7)^(A37-1),2) | E37: =Controls!$B$8+Controls!$B$9*(A37-1) | F37: =Controls!$B$10+INT((A37-1)/Controls!$B$11)*Controls!$B$12 | G37: =MIN(Controls!$B$15,Controls!$B$13+(A37-1)*Controls!$B$14) | H37: =ROUND(Controls!$B$16*(1+Controls!$B$17)^(A37-1),0) | I37: =ROUND(Controls!$B$18*(1+Controls!$B$19)^(A37-1),2)
A38: 35 | B38: =ROUND(Controls!$B$4*(A38^Controls!$B$5),0) | C38: =SUM($B$4:B38) | D38: =ROUND(Controls!$B$6*(1+Controls!$B$7)^(A38-1),2) | E38: =Controls!$B$8+Controls!$B$9*(A38-1) | F38: =Controls!$B$10+INT((A38-1)/Controls!$B$11)*Controls!$B$12 | G38: =MIN(Controls!$B$15,Controls!$B$13+(A38-1)*Controls!$B$14) | H38: =ROUND(Controls!$B$16*(1+Controls!$B$17)^(A38-1),0) | I38: =ROUND(Controls!$B$18*(1+Controls!$B$19)^(A38-1),2) | J38: Airdrop Claim Eligibility | K38: Airdrop target
A39: 36 | B39: =ROUND(Controls!$B$4*(A39^Controls!$B$5),0) | C39: =SUM($B$4:B39) | D39: =ROUND(Controls!$B$6*(1+Controls!$B$7)^(A39-1),2) | E39: =Controls!$B$8+Controls!$B$9*(A39-1) | F39: =Controls!$B$10+INT((A39-1)/Controls!$B$11)*Controls!$B$12 | G39: =MIN(Controls!$B$15,Controls!$B$13+(A39-1)*Controls!$B$14) | H39: =ROUND(Controls!$B$16*(1+Controls!$B$17)^(A39-1),0) | I39: =ROUND(Controls!$B$18*(1+Controls!$B$19)^(A39-1),2)
A40: 37 | B40: =ROUND(Controls!$B$4*(A40^Controls!$B$5),0) | C40: =SUM($B$4:B40) | D40: =ROUND(Controls!$B$6*(1+Controls!$B$7)^(A40-1),2) | E40: =Controls!$B$8+Controls!$B$9*(A40-1) | F40: =Controls!$B$10+INT((A40-1)/Controls!$B$11)*Controls!$B$12 | G40: =MIN(Controls!$B$15,Controls!$B$13+(A40-1)*Controls!$B$14) | H40: =ROUND(Controls!$B$16*(1+Controls!$B$17)^(A40-1),0) | I40: =ROUND(Controls!$B$18*(1+Controls!$B$19)^(A40-1),2)
A41: 38 | B41: =ROUND(Controls!$B$4*(A41^Controls!$B$5),0) | C41: =SUM($B$4:B41) | D41: =ROUND(Controls!$B$6*(1+Controls!$B$7)^(A41-1),2) | E41: =Controls!$B$8+Controls!$B$9*(A41-1) | F41: =Controls!$B$10+INT((A41-1)/Controls!$B$11)*Controls!$B$12 | G41: =MIN(Controls!$B$15,Controls!$B$13+(A41-1)*Controls!$B$14) | H41: =ROUND(Controls!$B$16*(1+Controls!$B$17)^(A41-1),0) | I41: =ROUND(Controls!$B$18*(1+Controls!$B$19)^(A41-1),2)
...

Sheet Upgrade_Params
A1: Upgrade Card Parameters
A3: Upgrade Name | B3: Category | C3: Unlock Level | D3: Base Cost | E3: Cost Growth | F3: Base Hourly Gain | G3: Gain Growth | H3: Max Tier | I3: Secondary Effect | J3: Effect per Tier | K3: Design Notes
A4: Tap Engine | B4: Mining | C4: 1 | D4: 50 | E4: 1.34 | F4: 15 | G4: 1.19 | H4: 15 | I4: Tap multiplier | J4: +1% every 5 tiers | K4: Starter efficiency anchor
A5: GPU Cluster | B5: Mining | C5: 2 | D5: 120 | E5: 1.35 | F5: 30 | G5: 1.2 | H5: 15 | I5: Energy restore | J5: +5 energy/min every 5 tiers | K5: Smooth early passive
A6: Referral Hub | B6: Community | C6: 3 | D6: 180 | E6: 1.33 | F6: 40 | G6: 1.18 | H6: 15 | I6: Referral bonus | J6: +1% referral reward per tier | K6: Quality social growth
A7: Liquidity Pool | B7: Exchange | C7: 4 | D7: 220 | E7: 1.34 | F7: 50 | G7: 1.19 | H7: 15 | I7: Offline yield | J7: +0.5% idle income per tier | K7: Economy stabilizer
A8: Streak Vault | B8: Community | C8: 5 | D8: 320 | E8: 1.35 | F8: 70 | G8: 1.19 | H8: 15 | I8: Daily bonus | J8: +2% daily bonus every 3 tiers | K8: Retention driver
A9: ASIC Vault | B9: Mining | C9: 6 | D9: 400 | E9: 1.37 | F9: 90 | G9: 1.21 | H9: 15 | I9: Tap crit chance | J9: +0.3% crit chance per tier | K9: Midgame power step
A10: Swap Router | B10: Exchange | C10: 8 | D10: 600 | E10: 1.36 | F10: 130 | G10: 1.2 | H10: 15 | I10: Market fee bonus | J10: +0.4% claim conversion per tier | K10: Early finance card
A11: Creator Bounties | B11: Community | C11: 10 | D11: 850 | E11: 1.35 | F11: 180 | G11: 1.19 | H11: 15 | I11: Quest reward | J11: +1.5% mission reward per tier | K11: UGC/social engine
A12: Wallet Vault | B12: Security | C12: 11 | D12: 900 | E12: 1.35 | F12: 170 | G12: 1.18 | H12: 15 | I12: Trust score | J12: +0.5 trust per tier | K12: Supports fast-lane reviews
A13: Quantum Cooler | B13: Mining | C13: 12 | D13: 1500 | E13: 1.39 | F13: 260 | G13: 1.22 | H13: 15 | I13: Max energy | J13: +15 max energy per tier | K13: Idle comfort
A14: AI Optimizer | B14: Research | C14: 13 | D14: 1600 | E14: 1.37 | F14: 320 | G14: 1.21 | H14: 15 | I14: Card synergy | J14: +0.4% all hourly per tier | K14: Compounding driver
A15: Fee Engine | B15: Exchange | C15: 14 | D15: 2500 | E15: 1.38 | F15: 480 | G15: 1.2 | H15: 15 | I15: Spread capture | J15: +0.5% passive cap per tier | K15: Late midgame finance
... A23: Whale Analytics | B23: Research | C23: 30 | D23: 22000 | E23: 1.42 | F23: 3300 | G23: 1.22 | H23: 15 | I23: VIP targeting | J23: +0.7% premium ROI per tier | K23: Endgame monetization

Sheet Upgrade_Tiers
A1: Per-Card Tier Pricing and Hourly Yield
A3: Category | B3: Upgrade Name | C3: Tier | D3: Unlock Level | E3: Cost (ADN) | F3: Added Hourly ADN | G3: Card Cumulative ADN/Hr | H3: Payback Hours | I3: Secondary Effect | J3: Effect/Tier | K3: Phase | L3: Efficiency Score
A4: =VLOOKUP(B4,Upgrade_Params!$A$4:$K$23,2,FALSE) | B4: Tap Engine | C4: 1 | D4: =VLOOKUP(B4,Upgrade_Params!$A$4:$K$23,3,FALSE) | E4: =ROUND(VLOOKUP(B4,Upgrade_Params!$A$4:$K$23,4,FALSE)*VLOOKUP(B4,Upgrade_Params!$A$4:$K$23,5,FALSE)^(C4-1),0) | F4: =ROUND(VLOOKUP(B4,Upgrade_Params!$A$4:$K$23,6,FALSE)*VLOOKUP(B4,Upgrade_Params!$A$4:$K$23,7,FALSE)^(C4-1),0) | G4: =SUMIFS($F$4:F4,$B$4:B4,B4) | H4: =IFERROR(E4/F4,0) | I4: =VLOOKUP(B4,Upgrade_Params!$A$4:$K$23,9,FALSE) | J4: =VLOOKUP(B4,Upgrade_Params!$A$4:$K$23,10,FALSE) | K4: =IF(D4<=6,"Starter",IF(D4<=15,"Midgame",IF(D4<=28,"Late Midgame","Endgame"))) | L4: =IFERROR(F4/E4*1000,0) | N4: Tier Model Checks
A5: =VLOOKUP(B5,Upgrade_Params!$A$4:$K$23,2,FALSE) | B5: Tap Engine | C5: 2 | D5: =VLOOKUP(B5,Upgrade_Params!$A$4:$K$23,3,FALSE) | E5: =ROUND(VLOOKUP(B5,Upgrade_Params!$A$4:$K$23,4,FALSE)*VLOOKUP(B5,Upgrade_Params!$A$4:$K$23,5,FALSE)^(C5-1),0) | F5: =ROUND(VLOOKUP(B5,Upgrade_Params!$A$4:$K$23,6,FALSE)*VLOOKUP(B5,Upgrade_Params!$A$4:$K$23,7,FALSE)^(C5-1),0) | G5: =SUMIFS($F$4:F5,$B$4:B5,B5) | H5: =IFERROR(E5/F5,0) | I5: =VLOOKUP(B5,Upgrade_Params!$A$4:$K$23,9,FALSE) | J5: =VLOOKUP(B5,Upgrade_Params!$A$4:$K$23,10,FALSE) | K5: =IF(D5<=6,"Starter",IF(D5<=15,"Midgame",IF(D5<=28,"Late Midgame","Endgame"))) | L5: =IFERROR(F5/E5*1000,0) | N5: Tier rows | O5: =COUNTA(B4:B303)
A6: =VLOOKUP(B6,Upgrade_Params!$A$4:$K$23,2,FALSE) | B6: Tap Engine | C6: 3 | D6: =VLOOKUP(B6,Upgrade_Params!$A$4:$K$23,3,FALSE) | E6: =ROUND(VLOOKUP(B6,Upgrade_Params!$A$4:$K$23,4,FALSE)*VLOOKUP(B6,Upgrade_Params!$A$4:$K$23,5,FALSE)^(C6-1),0) | F6: =ROUND(VLOOKUP(B6,Upgrade_Params!$A$4:$K$23,6,FALSE)*VLOOKUP(B6,Upgrade_Params!$A$4:$K$23,7,FALSE)^(C6-1),0) | G6: =SUMIFS($F$4:F6,$B$4:B6,B6) | H6: =IFERROR(E6/F6,0) | I6: =VLOOKUP(B6,Upgrade_Params!$A$4:$K$23,9,FALSE) | J6: =VLOOKUP(B6,Upgrade_Params!$A$4:$K$23,10,FALSE) | K6: =IF(D6<=6,"Starter",IF(D6<=15,"Midgame",IF(D6<=28,"Late Midgame","Endgame"))) | L6: =IFERROR(F6/E6*1000,0) | N6: Cards | O6: =COUNTA(Upgrade_Params!A4:A23)
A7: =VLOOKUP(B7,Upgrade_Params!$A$4:$K$23,2,FALSE) | B7: Tap Engine | C7: 4 | D7: =VLOOKUP(B7,Upgrade_Params!$A$4:$K$23,3,FALSE) | E7: =ROUND(VLOOKUP(B7,Upgrade_Params!$A$4:$K$23,4,FALSE)*VLOOKUP(B7,Upgrade_Params!$A$4:$K$23,5,FALSE)^(C7-1),0) | F7: =ROUND(VLOOKUP(B7,Upgrade_Params!$A$4:$K$23,6,FALSE)*VLOOKUP(B7,Upgrade_Params!$A$4:$K$23,7,FALSE)^(C7-1),0) | G7: =SUMIFS($F$4:F7,$B$4:B7,B7) | H7: =IFERROR(E7/F7,0) | I7: =VLOOKUP(B7,Upgrade_Params!$A$4:$K$23,9,FALSE) | J7: =VLOOKUP(B7,Upgrade_Params!$A$4:$K$23,10,FALSE) | K7: =IF(D7<=6,"Starter",IF(D7<=15,"Midgame",IF(D7<=28,"Late Midgame","Endgame"))) | L7: =IFERROR(F7/E7*1000,0) | N7: Avg payback hrs | O7: =AVERAGE(H4:H303)
A8: =VLOOKUP(B8,Upgrade_Params!$A$4:$K$23,2,FALSE) | B8: Tap Engine | C8: 5 | D8: =VLOOKUP(B8,Upgrade_Params!$A$4:$K$23,3,FALSE) | E8: =ROUND(VLOOKUP(B8,Upgrade_Params!$A$4:$K$23,4,FALSE)*VLOOKUP(B8,Upgrade_Params!$A$4:$K$23,5,FALSE)^(C8-1),0) | F8: =ROUND(VLOOKUP(B8,Upgrade_Params!$A$4:$K$23,6,FALSE)*VLOOKUP(B8,Upgrade_Params!$A$4:$K$23,7,FALSE)^(C8-1),0) | G8: =SUMIFS($F$4:F8,$B$4:B8,B8) | H8: =IFERROR(E8/F8,0) | I8: =VLOOKUP(B8,Upgrade_Params!$A$4:$K$23,9,FALSE) | J8: =VLOOKUP(B8,Upgrade_Params!$A$4:$K$23,10,FALSE) | K8: =IF(D8<=6,"Starter",IF(D8<=15,"Midgame",IF(D8<=28,"Late Midgame","Endgame"))) | L8: =IFERROR(F8/E8*1000,0) | N8: Max single purchase cost | O8: =MAX(E4:E303)
A9: =VLOOKUP(B9,Upgrade_Params!$A$4:$K$23,2,FALSE) | B9: Tap Engine | C9: 6 | D9: =VLOOKUP(B9,Upgrade_Params!$A$4:$K$23,3,FALSE) | E9: =ROUND(VLOOKUP(B9,Upgrade_Params!$A$4:$K$23,4,FALSE)*VLOOKUP(B9,Upgrade_Params!$A$4:$K$23,5,FALSE)^(C9-1),0) | F9: =ROUND(VLOOKUP(B9,Upgrade_Params!$A$4:$K$23,6,FALSE)*VLOOKUP(B9,Upgrade_Params!$A$4:$K$23,7,FALSE)^(C9-1),0) | G9: =SUMIFS($F$4:F9,$B$4:B9,B9) | H9: =IFERROR(E9/F9,0) | I9: =VLOOKUP(B9,Upgrade_Params!$A$4:$K$23,9,FALSE) | J9: =VLOOKUP(B9,Upgrade_Params!$A$4:$K$23,10,FALSE) | K9: =IF(D9<=6,"Starter",IF(D9<=15,"Midgame",IF(D9<=28,"Late Midgame","Endgame"))) | L9: =IFERROR(F9/E9*1000,0)
A10: =VLOOKUP(B10,Upgrade_Params!$A$4:$K$23,2,FALSE) | B10: Tap Engine | C10: 7 | D10: =VLOOKUP(B10,Upgrade_Params!$A$4:$K$23,3,FALSE) | E10: =ROUND(VLOOKUP(B10,Upgrade_Params!$A$4:$K$23,4,FALSE)*VLOOKUP(B10,Upgrade_Params!$A$4:$K$23,5,FALSE)^(C10-1),0) | F10: =ROUND(VLOOKUP(B10,Upgrade_Params!$A$4:$K$23,6,FALSE)*VLOOKUP(B10,Upgrade_Params!$A$4:$K$23,7,FALSE)^(C10-1),0) | G10: =SUMIFS($F$4:F10,$B$4:B10,B10) | H10: =IFERROR(E10/F10,0) | I10: =VLOOKUP(B10,Upgrade_Params!$A$4:$K$23,9,FALSE) | J10: =VLOOKUP(B10,Upgrade_Params!$A$4:$K$23,10,FALSE) | K10: =IF(D10<=6,"Starter",IF(D10<=15,"Midgame",IF(D10<=28,"Late Midgame","Endgame"))) | L10: =IFERROR(F10/E10*1000,0)
A11: =VLOOKUP(B11,Upgrade_Params!$A$4:$K$23,2,FALSE) | B11: Tap Engine | C11: 8 | D11: =VLOOKUP(B11,Upgrade_Params!$A$4:$K$23,3,FALSE) | E11: =ROUND(VLOOKUP(B11,Upgrade_Params!$A$4:$K$23,4,FALSE)*VLOOKUP(B11,Upgrade_Params!$A$4:$K$23,5,FALSE)^(C11-1),0) | F11: =ROUND(VLOOKUP(B11,Upgrade_Params!$A$4:$K$23,6,FALSE)*VLOOKUP(B11,Upgrade_Params!$A$4:$K$23,7,FALSE)^(C11-1),0) | G11: =SUMIFS($F$4:F11,$B$4:B11,B11) | H11: =IFERROR(E11/F11,0) | I11: =VLOOKUP(B11,Upgrade_Params!$A$4:$K$23,9,FALSE) | J11: =VLOOKUP(B11,Upgrade_Params!$A$4:$K$23,10,FALSE) | K11: =IF(D11<=6,"Starter",IF(D11<=15,"Midgame",IF(D11<=28,"Late Midgame","Endgame"))) | L11: =IFERROR(F11/E11*1000,0)
A12: =VLOOKUP(B12,Upgrade_Params!$A$4:$K$23,2,FALSE) | B12: Tap Engine | C12: 9 | D12: =VLOOKUP(B12,Upgrade_Params!$A$4:$K$23,3,FALSE) | E12: =ROUND(VLOOKUP(B12,Upgrade_Params!$A$4:$K$23,4,FALSE)*VLOOKUP(B12,Upgrade_Params!$A$4:$K$23,5,FALSE)^(C12-1),0) | F12: =ROUND(VLOOKUP(B12,Upgrade_Params!$A$4:$K$23,6,FALSE)*VLOOKUP(B12,Upgrade_Params!$A$4:$K$23,7,FALSE)^(C12-1),0) | G12: =SUMIFS($F$4:F12,$B$4:B12,B12) | H12: =IFERROR(E12/F12,0) | I12: =VLOOKUP(B12,Upgrade_Params!$A$4:$K$23,9,FALSE) | J12: =VLOOKUP(B12,Upgrade_Params!$A$4:$K$23,10,FALSE) | K12: =IF(D12<=6,"Starter",IF(D12<=15,"Midgame",IF(D12<=28,"Late Midgame","Endgame"))) | L12: =IFERROR(F12/E12*1000,0)
A13: =VLOOKUP(B13,Upgrade_Params!$A$4:$K$23,2,FALSE) | B13: Tap Engine | C13: 10 | D13: =VLOOKUP(B13,Upgrade_Params!$A$4:$K$23,3,FALSE) | E13: =ROUND(VLOOKUP(B13,Upgrade_Params!$A$4:$K$23,4,FALSE)*VLOOKUP(B13,Upgrade_Params!$A$4:$K$23,5,FALSE)^(C13-1),0) | F13: =ROUND(VLOOKUP(B13,Upgrade_Params!$A$4:$K$23,6,FALSE)*VLOOKUP(B13,Upgrade_Params!$A$4:$K$23,7,FALSE)^(C13-1),0) | G13: =SUMIFS($F$4:F13,$B$4:B13,B13) | H13: =IFERROR(E13/F13,0) | I13: =VLOOKUP(B13,Upgrade_Params!$A$4:$K$23,9,FALSE) | J13: =VLOOKUP(B13,Upgrade_Params!$A$4:$K$23,10,FALSE) | K13: =IF(D13<=6,"Starter",IF(D13<=15,"Midgame",IF(D13<=28,"Late Midgame","Endgame"))) | L13: =IFERROR(F13/E13*1000,0)
A14: =VLOOKUP(B14,Upgrade_Params!$A$4:$K$23,2,FALSE) | B14: Tap Engine | C14: 11 | D14: =VLOOKUP(B14,Upgrade_Params!$A$4:$K$23,3,FALSE) | E14: =ROUND(VLOOKUP(B14,Upgrade_Params!$A$4:$K$23,4,FALSE)*VLOOKUP(B14,Upgrade_Params!$A$4:$K$23,5,FALSE)^(C14-1),0) | F14: =ROUND(VLOOKUP(B14,Upgrade_Params!$A$4:$K$23,6,FALSE)*VLOOKUP(B14,Upgrade_Params!$A$4:$K$23,7,FALSE)^(C14-1),0) | G14: =SUMIFS($F$4:F14,$B$4:B14,B14) | H14: =IFERROR(E14/F14,0) | I14: =VLOOKUP(B14,Upgrade_Params!$A$4:$K$23,9,FALSE) | J14: =VLOOKUP(B14,Upgrade_Params!$A$4:$K$23,10,FALSE) | K14: =IF(D14<=6,"Starter",IF(D14<=15,"Midgame",IF(D14<=28,"Late Midgame","Endgame"))) | L14: =IFERROR(F14/E14*1000,0)
A15: =VLOOKUP(B15,Upgrade_Params!$A$4:$K$23,2,FALSE) | B15: Tap Engine | C15: 12 | D15: =VLOOKUP(B15,Upgrade_Params!$A$4:$K$23,3,FALSE) | E15: =ROUND(VLOOKUP(B15,Upgrade_Params!$A$4:$K$23,4,FALSE)*VLOOKUP(B15,Upgrade_Params!$A$4:$K$23,5,FALSE)^(C15-1),0) | F15: =ROUND(VLOOKUP(B15,Upgrade_Params!$A$4:$K$23,6,FALSE)*VLOOKUP(B15,Upgrade_Params!$A$4:$K$23,7,FALSE)^(C15-1),0) | G15: =SUMIFS($F$4:F15,$B$4:B15,B15) | H15: =IFERROR(E15/F15,0) | I15: =VLOOKUP(B15,Upgrade_Params!$A$4:$K$23,9,FALSE) | J15: =VLOOKUP(B15,Upgrade_Params!$A$4:$K$23,10,FALSE) | K15: =IF(D15<=6,"Starter",IF(D15<=15,"Midgame",IF(D15<=28,"Late Midgame","Endgame"))) | L15: =IFERROR(F15/E15*1000,0)
A16: =VLOOKUP(B16,Upgrade_Params!$A$4:$K$23,2,FALSE) | B16: Tap Engine | C16: 13 | D16: =VLOOKUP(B16,Upgrade_Params!$A$4:$K$23,3,FALSE) | E16: =ROUND(VLOOKUP(B16,Upgrade_Params!$A$4:$K$23,4,FALSE)*VLOOKUP(B16,Upgrade_Params!$A$4:$K$23,5,FALSE)^(C16-1),0) | F16: =ROUND(VLOOKUP(B16,Upgrade_Params!$A$4:$K$23,6,FALSE)*VLOOKUP(B16,Upgrade_Params!$A$4:$K$23,7,FALSE)^(C16-1),0) | G16: =SUMIFS($F$4:F16,$B$4:B16,B16) | H16: =IFERROR(E16/F16,0) | I16: =VLOOKUP(B16,Upgrade_Params!$A$4:$K$23,9,FALSE) | J16: =VLOOKUP(B16,Upgrade_Params!$A$4:$K$23,10,FALSE) | K16: =IF(D16<=6,"Starter",IF(D16<=15,"Midgame",IF(D16<=28,"Late Midgame","Endgame"))) | L16: =IFERROR(F16/E16*1000,0)
A17: =VLOOKUP(B17,Upgrade_Params!$A$4:$K$23,2,FALSE) | B17: Tap Engine | C17: 14 | D17: =VLOOKUP(B17,Upgrade_Params!$A$4:$K$23,3,FALSE) | E17: =ROUND(VLOOKUP(B17,Upgrade_Params!$A$4:$K$23,4,FALSE)*VLOOKUP(B17,Upgrade_Params!$A$4:$K$23,5,FALSE)^(C17-1),0) | F17: =ROUND(VLOOKUP(B17,Upgrade_Params!$A$4:$K$23,6,FALSE)*VLOOKUP(B17,Upgrade_Params!$A$4:$K$23,7,FALSE)^(C17-1),0) | G17: =SUMIFS($F$4:F17,$B$4:B17,B17) | H17: =IFERROR(E17/F17,0) | I17: =VLOOKUP(B17,Upgrade_Params!$A$4:$K$23,9,FALSE) | J17: =VLOOKUP(B17,Upgrade_Params!$A$4:$K$23,10,FALSE) | K17: =IF(D17<=6,"Starter",IF(D17<=15,"Midgame",IF(D17<=28,"Late Midgame","Endgame"))) | L17: =IFERROR(F17/E17*1000,0)
A18: =VLOOKUP(B18,Upgrade_Params!$A$4:$K$23,2,FALSE) | B18: Tap Engine | C18: 15 | D18: =VLOOKUP(B18,Upgrade_Params!$A$4:$K$23,3,FALSE) | E18: =ROUND(VLOOKUP(B18,Upgrade_Params!$A$4:$K$23,4,FALSE)*VLOOKUP(B18,Upgrade_Params!$A$4:$K$23,5,FALSE)^(C18-1),0) | F18: =ROUND(VLOOKUP(B18,Upgrade_Params!$A$4:$K$23,6,FALSE)*VLOOKUP(B18,Upgrade_Params!$A$4:$K$23,7,FALSE)^(C18-1),0) | G18: =SUMIFS($F$4:F18,$B$4:B18,B18) | H18: =IFERROR(E18/F18,0) | I18: =VLOOKUP(B18,Upgrade_Params!$A$4:$K$23,9,FALSE) | J18: =VLOOKUP(B18,Upgrade_Params!$A$4:$K$23,10,FALSE) | K18: =IF(D18<=6,"Starter",IF(D18<=15,"Midgame",IF(D18<=28,"Late Midgame","Endgame"))) | L18: =IFERROR(F18/E18*1000,0)
A19: =VLOOKUP(B19,Upgrade_Params!$A$4:$K$23,2,FALSE) | B19: GPU Cluster | C19: 1 | D19: =VLOOKUP(B19,Upgrade_Params!$A$4:$K$23,3,FALSE) | E19: =ROUND(VLOOKUP(B19,Upgrade_Params!$A$4:$K$23,4,FALSE)*VLOOKUP(B19,Upgrade_Params!$A$4:$K$23,5,FALSE)^(C19-1),0) | F19: =ROUND(VLOOKUP(B19,Upgrade_Params!$A$4:$K$23,6,FALSE)*VLOOKUP(B19,Upgrade_Params!$A$4:$K$23,7,FALSE)^(C19-1),0) | G19: =SUMIFS($F$4:F19,$B$4:B19,B19) | H19: =IFERROR(E19/F19,0) | I19: =VLOOKUP(B19,Upgrade_Params!$A$4:$K$23,9,FALSE) | J19: =VLOOKUP(B19,Upgrade_Params!$A$4:$K$23,10,FALSE) | K19: =IF(D19<=6,"Starter",IF(D19<=15,"Midgame",IF(D19<=28,"Late Midgame","Endgame"))) | L19: =IFERROR(F19/E19*1000,0)
A20: =VLOOKUP(B20,Upgrade_Params!$A$4:$K$23,2,FALSE) | B20: GPU Cluster | C20: 2 | D20: =VLOOKUP(B20,Upgrade_Params!$A$4:$K$23,3,FALSE) | E20: =ROUND(VLOOKUP(B20,Upgrade_Params!$A$4:$K$23,4,FALSE)*VLOOKUP(B20,Upgrade_Params!$A$4:$K$23,5,FALSE)^(C20-1),0) | F20: =ROUND(VLOOKUP(B20,Upgrade_Params!$A$4:$K$23,6,FALSE)*VLOOKUP(B20,Upgrade_Params!$A$4:$K$23,7,FALSE)^(C20-1),0) | G20: =SUMIFS($F$4:F20,$B$4:B20,B20) | H20: =IFERROR(E20/F20,0) | I20: =VLOOKUP(B20,Upgrade_Params!$A$4:$K$23,9,FALSE) | J20: =VLOOKUP(B20,Upgrade_Params!$A$4:$K$23,10,FALSE) | K20: =IF(D20<=6,"Starter",IF(D20<=15,"Midgame",IF(D20<=28,"Late Midgame","Endgame"))) | L20: =IFERROR(F20/E20*1000,0)
... A303: =VLOOKUP(B303,Upgrade_Params!$A$4:$K$23,2,FALSE) | B303: Whale Analytics | C303: 15 | D303: =VLOOKUP(B303,Upgrade_Params!$A$4:$K$23,3,FALSE) | E303: =ROUND(VLOOKUP(B303,Upgrade_Params!$A$4:$K$23,4,FALSE)*VLOOKUP(B303,Upgrade_Params!$A$4:$K$23,5,FALSE)^(C303-1),0) | F303: =ROUND(VLOOKUP(B303,Upgrade_Params!$A$4:$K$23,6,FALSE)*VLOOKUP(B303,Upgrade_Params!$A$4:$K$23,7,FALSE)^(C303-1),0) | G303: =SUMIFS($F$4:F303,$B$4:B303,B303) | H303: =IFERROR(E303/F303,0) | I303: =VLOOKUP(B303,Upgrade_Params!$A$4:$K$23,9,FALSE) | J303: =VLOOKUP(B303,Upgrade_Params!$A$4:$K$23,10,FALSE) | K303: =IF(D303<=6,"Starter",IF(D303<=15,"Midgame",IF(D303<=28,"Late Midgame","Endgame"))) | L303: =IFERROR(F303/E303*1000,0)

Sheet Referral_Quests
A1: Referral Progression Chain
A3: Chain | B3: Stage | C3: Unlock Level | D3: Task | E3: Requirement Detail | F3: Reward ADN | G3: Reward Weight | H3: Bonus Reward | I3: Completion Check | J3: Anti-Abuse Rule | K3: Next Task Logic
A4: Starter | B4: 1 | C4: 8 | D4: Invite 1 friend | E4: Referral joins via your code | F4: 300 | G4: 10 | H4: Bronze inviter badge | I4: Referral account created + tutorial done | J4: No same device / same IP | K4: Open Stage 2
A5: Starter | B5: 2 | C5: 8 | D5: Make referral active | E5: Referral reaches Level 3 | F5: 500 | G5: 18 | H5: 1h 2x tap boost | I5: At least 2 sessions across 2 hours | J5: Reject if account age < 30 min | K5: Open Stage 3
A6: Starter | B6: 3 | C6: 8 | D6: Referral earns ADN | E6: Referral earns 100 ADN | F6: 650 | G6: 24 | H6: Energy refill pack | I6: Server-side earnings check | J6: No burst-only taps | K6: Open Stage 4
A7: Growth | B7: 4 | C7: 10 | D7: Bring 2 active referrals | E7: 2 referrals reach Level 4 | F7: 1200 | G7: 40 | H7: Creator bounty ticket | I7: Distinct device fingerprint | J7: Max 1 reward / household unless reviewed | K7: Open Stage 5
A8: Growth | B8: 5 | C8: 10 | D8: Referral streak | E8: 1 referral logs in 3 days in a row | F8: 1500 | G8: 55 | H8: Daily bonus +10% for 24h | I8: Consecutive UTC-day claims | J8: No emulator clusters | K8: Open Stage 6
A9: Quality | B9: 6 | C9: 12 | D9: Referral taps consistently | E9: 1 referral performs 200 valid taps | F9: 1800 | G9: 70 | H9: Quantum cooler shard | I9: Anti-cheat valid tap counter | J9: Ignore locked users | K9: Open Stage 7
A10: Quality | B10: 7 | C10: 12 | D10: Idle progression | E10: 1 referral claims offline earnings twice | F10: 2200 | G10: 85 | H10: Idle cap +0.5h for 24h | I10: Two separate offline claim timestamps | J10: No script-like cadence | K10: Open Stage 8
A11: Scale | B11: 8 | C11: 15 | D11: Bring 3 engaged referrals | E11: 3 referrals reach Level 6 | F11: 3200 | G11: 120 | H11: Premium market ticket | I11: Level + session + spend depth | J11: No self-invite graph loops | K11: Open Stage 9
A12: Scale | B12: 9 | C12: 15 | D12: Monetized social proof | E12: 1 referral buys any premium boost | F12: 4000 | G12: 160 | H12: Premium chest | I12: Payment success webhook | J12: No refunded / test payments | K12: Open Stage 10
A13: Retention | B13: 10 | C13: 18 | D13: Referral guild join | E13: 2 referrals join or create guild | F13: 5200 | G13: 210 | H13: Guild booster | I13: Guild membership age > 24h | J13: One guild loop only | K13: Open Stage 11
A14: Retention | B14: 11 | C14: 18 | D14: 7-day referral retention | E14: 1 referral active on day 7 | F14: 7000 | G14: 280 | H14: 7-day aura badge | I14: D1 + D3 + D7 activity | J14: Filter suspicious clusters | K14: Open Stage 12
A15: Power | B15: 12 | C15: 22 | D15: High-value referral | E15: 1 referral reaches Level 12 | F15: 10000 | G15: 380 | H15: Auto-tap drone shard | I15: Progression verified server-side | J15: No unusual spend spike | K15: Open Stage 13
... A18: Elite | B18: 15 | C18: 35 | D18: Claim-ready referral tree | E18: 3 referrals become airdrop-eligible | F18: 30000 | G18: 1000 | H18: Fast-lane claim review | I18: Eligibility status true on 3 nodes | J18: Manual review allowed | K18: Season reset / prestige quest

Sheet Mission_Engine
A1: Segment-Based Next Quest Logic
A3: Player Segment | B3: Primary Trigger | C3: Recommended Next Quest | D3: Reason | E3: Reward Mix | F3: Cooldown | G3: When to Avoid | H3: Notes | I3: AI Prompt Hint
A4: New user | B4: Finished tutorial | C4: Buy 2 starter cards and claim daily bonus | D4: Teaches spend loop | E4: 70% ADN / 30% energy | F4: No cooldown | G4: If user already L4+ | H4: Keep copy short and encouraging
A5: Daily user | B5: Claimed daily bonus | C5: Play 3 short sessions today | D5: Build habit density | E5: 60% ADN / 40% streak XP | F5: 12h | G5: If session fatigue detected | H5: Push consistency over grind
A6: Referral-focused | B6: Completed referral stage | C6: Invite 1 more friend who reaches L3 | D6: Extends social loop with quality filter | E6: 50% ADN / 50% weight | F6: 18h | G6: If suspicious network score high | H6: Reward active referrals only
A7: Cooling | B7: No login for 36h | C7: Return and finish 1 comeback mission | D7: Reactivation before churn hardens | E7: 40% ADN / 60% boost | F7: 24h | G7: If user opted out of notifications | H7: Use loss aversion copy
A8: Active grinder | B8: 5+ sessions in 2 days | C8: Upgrade one midgame exchange card | D8: Convert activity into compounding | E8: 80% ADN / 20% badge | F8: 8h | G8: If user short on ADN | H8: Recommend best payback card
A9: Idle lover | B9: Multiple offline claims | C9: Increase idle cap via Liquidity Pool or Auto-Tap Drones | D9: Supports preferred playstyle | E9: 70% ADN / 30% idle boost | F9: 12h | G9: If passive cap already maxed | H9: Offer comfort not grind
A10: Mid spender | B10: Bought premium once | C10: Unlock Premium Market synergy combo | D10: Nudge repeat purchase without hard pressure | E10: 40% ADN / 30% premium chest / 30% weight | F10: 24h | G10: If refund risk or low trust | H10: Use soft-sell language
A11: Whale | B11: Bought premium multiple times | C11: Complete elite combo card upgrade | D11: Retain high-value users | E11: 30% ADN / 20% badge / 50% VIP perk | F11: 36h | G11: If progression cap reached | H11: Focus prestige and exclusivity
A12: Suspicious | B12: High fraud score | C12: Manual review or trust-restoring mission | D12: Reduce false positives and loss | E12: Mostly non-economic rewards | F12: 48h | G12: If already banned | H12: Do not grant weight rewards
A13: Claim-ready | B13: Level 35+ and trusted | C13: Finish proof-of-quality task pack | D13: Prepare for airdrop / payout ops | E13: 20% ADN / 80% weight | F13: 72h | G13: If KYC/compliance incomplete | H13: Operational checklist messaging

Sheet Dashboard
A1: ADN Economy Dashboard
D3: Balancing Notes
A4: Total Levels | B4: =MAX(Player_Levels!A4:A53) | D4: • Early cards pay back faster to create momentum.
A5: Total Upgrade Cards | B5: =COUNTA(Upgrade_Params!A4:A23) | D5: • Midgame payback stretches modestly to create choice tension.
A6: Total Tier Rows | B6: =COUNTA(Upgrade_Tiers!B4:B273) | D6: • Endgame costs rise faster than gains, but synergy cards preserve aspiration.
A7: Starter Avg Payback Hrs | B7: =IFERROR(SUMIF(Upgrade_Tiers!K4:K303,"Starter",Upgrade_Tiers!H4:H303)/COUNTIF(Upgrade_Tiers!K4:K303,"Starter"),0) | D7: • Referral rewards favor active and retained referrals over raw invites.
A8: Midgame Avg Payback Hrs | B8: =IFERROR(SUMIF(Upgrade_Tiers!K4:K303,"Midgame",Upgrade_Tiers!H4:H303)/COUNTIF(Upgrade_Tiers!K4:K303,"Midgame"),0) | D8: • Unlock pacing separates retention systems, social systems, and monetization sinks.
A9: Endgame Avg Payback Hrs | B9: =IFERROR(SUMIF(Upgrade_Tiers!K4:K303,"Endgame",Upgrade_Tiers!H4:H303)/COUNTIF(Upgrade_Tiers!K4:K303,"Endgame"),0)
A10: Level 15 Tap Reward | B10: =INDEX(Player_Levels!D4:D53,15)
A11: Level 35 Passive Cap / Hr | B11: =INDEX(Player_Levels!H4:H53,35)
A12: Chart Data | E12: Tier 1 Efficiency by Card
A13: Level | B13: Cumulative XP | C13: Passive Cap / Hr | E13: Card | F13: Tier1 Cost | G13: Tier1 Added ADN/Hr
A14: =Player_Levels!A4 | B14: =Player_Levels!C4 | C14: =Player_Levels!H4 | E14: Tap Engine | F14: =Upgrade_Params!D4 | G14: =Upgrade_Params!F4
A15: =Player_Levels!A5 | B15: =Player_Levels!C5 | C15: =Player_Levels!H5 | E15: GPU Cluster | F15: =Upgrade_Params!D5 | G15: =Upgrade_Params!F5
A16: =Player_Levels!A6 | B16: =Player_Levels!C6 | C16: =Player_Levels!H6 | E16: Referral Hub | F16: =Upgrade_Params!D6 | G16: =Upgrade_Params!F6
A17: =Player_Levels!A7 | B17: =Player_Levels!C7 | C17: =Player_Levels!H7 | E17: Liquidity Pool | F17: =Upgrade_Params!D7 | G17: =Upgrade_Params!F7
A18: =Player_Levels!A8 | B18: =Player_Levels!C8 | C18: =Player_Levels!H8 | E18: Streak Vault | F18: =Upgrade_Params!D8 | G18: =Upgrade_Params!F8
A19: =Player_Levels!A9 | B19: =Player_Levels!C9 | C19: =Player_Levels!H9 | E19: ASIC Vault | F19: =Upgrade_Params!D9 | G19: =Upgrade_Params!F9
A20: =Player_Levels!A10 | B20: =Player_Levels!C10 | C20: =Player_Levels!H10 | E20: Swap Router | F20: =Upgrade_Params!D10 | G20: =Upgrade_Params!F10
A21: =Player_Levels!A11 | B21: =Player_Levels!C11 | C21: =Player_Levels!H11 | E21: Creator Bounties | F21: =Upgrade_Params!D11 | G21: =Upgrade_Params!F11
A22: =Player_Levels!A12 | B22: =Player_Levels!C12 | C22: =Player_Levels!H12 | E22: Wallet Vault | F22: =Upgrade_Params!D12 | G22: =Upgrade_Params!F12
A23: =Player_Levels!A13 | B23: =Player_Levels!C13 | C23: =Player_Levels!H13 | E23: Quantum Cooler | F23: =Upgrade_Params!D13 | G23: =Upgrade_Params!F13
A24: =Player_Levels!A14 | B24: =Player_Levels!C14 | C24: =Player_Levels!H14 | E24: AI Optimizer | F24: =Upgrade_Params!D14 | G24: =Upgrade_Params!F14
A25: =Player_Levels!A15 | B25: =Player_Levels!C15 | C25: =Player_Levels!H15 | E25: Fee Engine | F25: =Upgrade_Params!D15 | G25: =Upgrade_Params!F15
... A33: =Player_Levels!A23 | B33: =Player_Levels!C23 | C33: =Player_Levels!H23 | E33: Whale Analytics | F33: =Upgrade_Params!D23 | G33: =Upgrade_Params!F23
A34: =Player_Levels!A24 | B34: =Player_Levels!C24 | C34: =Player_Levels!H24
A35: =Player_Levels!A25 | B35: =Player_Levels!C25 | C35: =Player_Levels!H25
A36: =Player_Levels!A26 | B36: =Player_Levels!C26 | C36: =Player_Levels!H26
A37: =Player_Levels!A27 | B37: =Player_Levels!C27 | C37: =Player_Levels!H27
A38: =Player_Levels!A28 | B38: =Player_Levels!C28 | C38: =Player_Levels!H28
A39: =Player_Levels!A29 | B39: =Player_Levels!C29 | C39: =Player_Levels!H29
A40: =Player_Levels!A30 | B40: =Player_Levels!C30 | C40: =Player_Levels!H30
A41: =Player_Levels!A31 | B41: =Player_Levels!C31 | C41: =Player_Levels!H31
A42: =Player_Levels!A32 | B42: =Player_Levels!C32 | C42: =Player_Levels!H32
A43: =Player_Levels!A33 | B43: =Player_Levels!C33 | C43: =Player_Levels!H33
A44: =Player_Levels!A34 | B44: =Player_Levels!C34 | C44: =Player_Levels!H34
A45: =Player_Levels!A35 | B45: =Player_Levels!C35 | C45: =Player_Levels!H35
... A63: =Player_Levels!A53 | B63: =Player_Levels!C53 | C63: =Player_Levels!H53
